<?xml version="1.0"?>
<robot name="rrl_bot_cam_ctrl">
  <material name="gray1">
    <color rgba="0.3 0.3 0.3 1"/>
  </material>

  <material name="gray2">
    <color rgba="0.5 0.5 0.5 1"/>
  </material>

  <material name="gray3">
    <color rgba="0.8 0.8 0.8 1"/>
  </material>

  <material name="black">
    <color rgba="0.0 0.0 0.0 1"/>
  </material>

  <material name="orange">
    <color rgba="1.0 0.5 0.0 1"/>
  </material>

  <link name="base">
    <visual>
      <geometry>
        <box size="0.2 0.2 0.5"/>
      </geometry>
      <origin xyz="0 0 0.25" rpy="0 0 0"/>
      <material name="black"/>
    </visual>
    <collision>
      <geometry>
        <box size="0.2 0.2 0.5"/>
      </geometry>
      <origin xyz="0 0 0.25" rpy="0 0 0"/>
    </collision>
    <inertial>
      <origin xyz="0 0 0.25" rpy="0 0 0"/>
      <mass value="10"/>
      <inertia ixx="0.24"  ixy="0"  ixz="0" iyy="0.24" iyz="0" izz="0.066" />
    </inertial>
  </link>

  <link name="link1">
    <visual>
      <geometry>
        <cylinder length="0.05" radius="0.1"/>
      </geometry>
      <origin xyz="0 0 0.025" rpy="0 0 0"/>
      <material name="gray3"/>
    </visual>
    <visual>
      <geometry>
        <box size="0.7 0.2 0.05"/>
      </geometry>
      <origin xyz="0.25 0 0.075" rpy="0 0 0"/>
      <material name="gray3"/>
    </visual>
    <collision>
      <geometry>
        <cylinder length="0.05" radius="0.1"/>
      </geometry>
      <origin xyz="0 0 0.025" rpy="0 0 0"/>
    </collision>
    <collision>
      <geometry>
        <box size="0.7 0.2 0.05"/>
      </geometry>
      <origin xyz="0.25 0 0.075" rpy="0 0 0"/>
    </collision>
    <inertial>
      <origin xyz="0.25 0 0.075" rpy="0 0 0"/>
      <mass value="0.5"/>
      <inertia ixx="0.0017"  ixy="0"  ixz="0" iyy="0.0205" iyz="0" izz="0.022" />
    </inertial>
  </link>

  <link name="link2">
    <visual>
      <geometry>
        <cylinder length="0.03" radius="0.07"/>
      </geometry>
      <origin xyz="0 0 0.015" rpy="0 0 0"/>
      <material name="gray2"/>
    </visual>
    <visual>
      <geometry>
        <box size="0.4 0.14 0.03"/>
      </geometry>
      <origin xyz="0.13 0 0.045" rpy="0 0 0"/>
      <material name="gray2"/>
    </visual>
    <visual>
      <geometry>
        <box size="0.1 0.1 0.1"/>
      </geometry>
      <origin xyz="0.28 0 0.11" rpy="0 0 0"/>
      <material name="gray2"/>
    </visual>
    <collision>
      <geometry>
        <cylinder length="0.03" radius="0.07"/>
      </geometry>
      <origin xyz="0 0 0.015" rpy="0 0 0"/>
    </collision>
    <collision>
      <geometry>
        <box size="0.27 0.14 0.03"/>
      </geometry>
      <origin xyz="0.13 0 0.045" rpy="0 0 0"/>
    </collision>
    <collision>
      <geometry>
        <box size="0.1 0.1 0.1"/>
      </geometry>
      <origin xyz="0.28 0 0.11" rpy="0 0 0"/>
    </collision>
    <inertial>
      <origin xyz="0.13 0 0.045" rpy="0 0 0"/>
      <mass value="0.3"/>
      <inertia ixx="0.0005"  ixy="0"  ixz="0" iyy="0.004" iyz="0" izz="0.0045" />
    </inertial>
  </link>

  <link name="link3">
    <visual>
      <geometry>
        <box size="0.06 0.06 0.7"/>
      </geometry>
      <origin xyz="0 0 0.35" rpy="0 0 0"/>
      <material name="gray1"/>
    </visual>
    <collision>
      <geometry>
        <box size="0.06 0.06 0.7"/>
      </geometry>
      <origin xyz="0 0 0.35" rpy="0 0 0"/>
    </collision>
    <inertial>
      <origin xyz="0 0 0.35" rpy="0 0 0"/>
      <mass value="0.2"/>
      <inertia ixx="0.0082"  ixy="0"  ixz="0" iyy="0.0082" iyz="0" izz="0.00012" />
    </inertial>
  </link>

  <link name="ee">
    <visual>
      <geometry>
        <sphere radius="0.03"/>
      </geometry>
      <origin xyz="0 0 0" rpy="0 0 0"/>
      <material name="orange"/>
    </visual>
    <collision>
      <geometry>
        <sphere radius="0.03"/>
      </geometry>
      <origin xyz="0 0 0" rpy="0 0 0"/>
    </collision>
    <inertial>
      <origin xyz="0 0 0" rpy="0 0 0"/>
      <mass value="0.1"/>
      <inertia ixx="0.000036"  ixy="0"  ixz="0" iyy="0.000036" iyz="0" izz="0.000036" />
    </inertial>
  </link>

  <joint name="joint1" type="revolute">
      <origin xyz="0 0 0.5" rpy="0 0 0"/>
      <parent link="base"/>
      <child link="link1"/>
      <axis xyz="0 0 1"/>
      <limit lower="-2" upper="2" effort="1000" velocity="1"/>
  </joint>

  <joint name="joint2" type="revolute">
      <origin xyz="0.53 0 0.1" rpy="0 0 0"/>
      <parent link="link1"/>
      <child link="link2"/>
      <axis xyz="0 0 1"/>
      <limit lower="-2" upper="2" effort="1000" velocity="1"/>
  </joint>

  <joint name="joint3" type="prismatic">
      <origin xyz="0.28 0 0.60" rpy="3.14 0 0"/>
      <parent link="link2"/>
      <child link="link3"/>
      <axis xyz="0 0 1"/>
      <limit lower="0" upper="0.5" effort="1000" velocity="1"/>
  </joint>

  <joint name="ee_joint" type="fixed">
      <origin xyz="0 0 0.7" rpy="0 0 0"/>
      <parent link="link3"/>
      <child link="ee"/>
  </joint>
  <gazebo reference="ee_joint">
    <preserveFixedJoint>true</preserveFixedJoint>
  </gazebo>

  <!-- Add camera START -->
  <joint name="camera_joint" type="fixed">
      <origin xyz="0 0 0" rpy="3.14159 0 0"/>
      <parent link="ee"/>
      <child link="camera"/>
  </joint>
  <gazebo reference="camera_joint">
    <preserveFixedJoint>true</preserveFixedJoint>
  </gazebo>

  <link name="camera">
    <inertial>
      <origin xyz="0 0 0" rpy="0 0 0"/>
      <mass value="1e-5"/>
      <inertia ixx="1e-6"  ixy="0"  ixz="0" iyy="1e-6" iyz="0" izz="1e-6" />
    </inertial>
  </link>

  <joint name="camera_optical_joint" type="fixed">
      <origin xyz="0 0 0" rpy="-1.5708 0 -1.5708"/>
      <parent link="camera"/>
      <child link="camera_optical_frame"/>
  </joint>
  <gazebo reference="camera_optical_joint">
    <preserveFixedJoint>true</preserveFixedJoint>
  </gazebo>

  <link name="camera_optical_frame">
    <inertial>
      <origin xyz="0 0 0" rpy="0 0 0"/>
      <mass value="1e-5"/>
      <inertia ixx="1e-6"  ixy="0"  ixz="0" iyy="1e-6" iyz="0" izz="1e-6" />
    </inertial>
  </link>

  <gazebo reference="camera">
    <sensor name="camera" type="camera">
      <camera>
        <horizontal_fov>1.047</horizontal_fov>
        <image>
          <width>640</width>
          <height>480</height>
        </image>
        <clip>
          <near>0.1</near>
          <far>100</far>
        </clip>
        <optical_frame_id>camera_optical_frame</optical_frame_id>
      </camera>
      <always_on>1</always_on>
      <update_rate>30</update_rate>
      <visualize>true</visualize>
      <topic>camera</topic>
    </sensor>
  </gazebo>

  <gazebo>
    <plugin
      filename="gz-sim-sensors-system"
      name="gz::sim::systems::Sensors">
    </plugin>
  </gazebo>
  <!-- Add camera END -->

  <!-- Add ros2_control START -->
  <ros2_control name="joint1_controller" type="system">
    <hardware>
      <plugin>gz_ros2_control/GazeboSimSystem</plugin>
    </hardware>
    <joint name="joint1">
      <state_interface name="position" />
      <state_interface name="velocity" />
      <command_interface name="position" />
    </joint>
  </ros2_control>
  <ros2_control name="joint2_controller" type="system">
    <hardware>
      <plugin>gz_ros2_control/GazeboSimSystem</plugin>
    </hardware>
    <joint name="joint2">
      <state_interface name="position" />
      <state_interface name="velocity" />
      <command_interface name="position" />
    </joint>
  </ros2_control>
  <ros2_control name="joint3_controller" type="system">
    <hardware>
      <plugin>gz_ros2_control/GazeboSimSystem</plugin>
    </hardware>
    <joint name="joint3">
      <state_interface name="position" />
      <state_interface name="velocity" />
      <command_interface name="position" />
    </joint>
  </ros2_control>

  <gazebo>
    <plugin
      filename="gz_ros2_control-system"
      name="gz_ros2_control::GazeboSimROS2ControlPlugin">
      <!-- Must launch gazebo in the right directory relative to hardcoded path.
           No good solution to parameters path without using xacro. -->
      <parameters>src/rfp_gz_intro/config/rrl_bot_controller.yaml</parameters>
    </plugin>
  </gazebo>
  <!-- Add ros2_control END -->
</robot>
